<?xml version="1.0"?>
<robot name="room_scanner">
  <link name="base">
    <visual>
      <geometry>
        <cylinder length="0.102" radius="0.0381"/>
      </geometry>
    </visual>
  </link>

  <link name="camera">
    <visual>
      <geometry>
        <box size="0.1524 0.0254 0.0762"/>
      </geometry>
    </visual>
  </link>

  <joint name="id_1" type="revolute">
    <origin xyz="0 0 0.0891"/>
    <parent link="base"/>
    <child link="camera"/>
    <axis xyz="0 0 1"/>
    <limit lower="-2.5" upper="2.5" velocity="12.0" effort="2.0"/>
  </joint>
</robot>
